libGL error: MESA-LOADER: failed to open nouveau: /usr/lib/dri/nouveau_dri.so: cannot open shared object file: No such file or directory (search paths /usr/lib/x86_64-linux-gnu/dri:\$${ORIGIN}/dri:/usr/lib/dri, suffix _dri)
libGL error: failed to load driver: nouveau
libGL error: MESA-LOADER: failed to open swrast: /usr/lib/dri/swrast_dri.so: cannot open shared object file: No such file or directory (search paths /usr/lib/x86_64-linux-gnu/dri:\$${ORIGIN}/dri:/usr/lib/dri, suffix _dri)
libGL error: failed to load driver: swrast
Traceback (most recent call last):
  File "ppxf_kinematics_SLACS_lens_SDSSJ0330-0020.py", line 114, in <module>
    plot=True)
  File "/local/shawnknabel/anaconda3/envs/astroconda/lib/python3.7/site-packages/ppxf/kcwi_util.py", line 147, in ppxf_kinematics_RXJ1131_getGlobal_lens_deredshift
    hdu = fits.open(file)
  File "/local/shawnknabel/anaconda3/envs/astroconda/lib/python3.7/site-packages/astropy/io/fits/hdu/hdulist.py", line 174, in fitsopen
    lazy_load_hdus, ignore_missing_simple, **kwargs)
  File "/local/shawnknabel/anaconda3/envs/astroconda/lib/python3.7/site-packages/astropy/io/fits/hdu/hdulist.py", line 411, in fromfile
    lazy_load_hdus=lazy_load_hdus, **kwargs)
  File "/local/shawnknabel/anaconda3/envs/astroconda/lib/python3.7/site-packages/astropy/io/fits/hdu/hdulist.py", line 1064, in _readfrom
    fileobj = _File(fileobj, mode=mode, memmap=memmap, cache=cache)
  File "/local/shawnknabel/anaconda3/envs/astroconda/lib/python3.7/site-packages/astropy/utils/decorators.py", line 536, in wrapper
    return function(*args, **kwargs)
  File "/local/shawnknabel/anaconda3/envs/astroconda/lib/python3.7/site-packages/astropy/io/fits/file.py", line 170, in __init__
    self._open_filename(fileobj, mode, overwrite)
  File "/local/shawnknabel/anaconda3/envs/astroconda/lib/python3.7/site-packages/astropy/io/fits/file.py", line 558, in _open_filename
    self._file = fileobj_open(self.name, IO_FITS_MODES[mode])
  File "/local/shawnknabel/anaconda3/envs/astroconda/lib/python3.7/site-packages/astropy/io/fits/util.py", line 390, in fileobj_open
    return open(filename, mode, buffering=0)
FileNotFoundError: [Errno 2] No such file or directory: '/local/shawnknabel/data/CF_mosaics/SDSSJ0330-0020/J0330_central_spectrum.fits'
